Workbook

Sheet Excel2LaTeX
A1: RangeAddress | B1: Options | C1: CellWidth | D1: Indent | E1: FileName
A2: =COUNT(#REF!) -> 0 | B2: 7 | C2: 5 | D2: 0 | E2: du toan mau.tex

Sheet Tong hop
A1: III. PHÂN BỔ KINH PHÍ THỰC HIỆN
A2: 24. Cơ cấu phân bổ kinh phí
E3: Đơn vị tính: Đồng
A4: STT | B4: Nội dung các khoản chi | C4: Tổng kinh phí | E4: Nguồn vốn
C5: Khoán chi | D5: Ngoài khoán | E5: NSNN | F5: Khác
A6: 1 | B6: Công lao động trực tiếp | C6: ='Chi tiet'!F5 -> 849747000 | E6: ='Chi tiet'!H5 -> 849747000
A7: 2 | B7: Nguyên, nhiên liệu, vât tư, phụ tùng, dụng cụ, năng lượng, tài liệu, số liệu, … | C7: ='Chi tiet'!F129 -> 0 | D7: ='Chi tiet'!G129 -> 0 | E7: ='Chi tiet'!H129 -> 0 | F7: ='Chi tiet'!I129 -> 0
A8: 3 | B8: Công tác trong nước | C8: ='Chi tiet'!F130 -> 0 | D8: ='Chi tiet'!G130 -> 0 | E8: ='Chi tiet'!H130 -> 0 | F8: ='Chi tiet'!I130 -> 0
A9: 4 | B9: Chi điều tra, khảo sát | C9: ='Chi tiet'!F131 -> 0 | D9: ='Chi tiet'!G131 -> 0 | E9: ='Chi tiet'!H131 -> 0 | F9: ='Chi tiet'!I131 -> 0
A10: 5 | B10: Chi văn phòng phẩm, in ấn | C10: ='Chi tiet'!F132 -> 1003000 | D10: ='Chi tiet'!G132 -> 0 | E10: ='Chi tiet'!H132 -> 1003000 | F10: ='Chi tiet'!I132 -> 0
A11: 6 | B11: Chi hội thảo khoa học | C11: ='Chi tiet'!F133 -> 0 | D11: ='Chi tiet'!G133 -> 0 | E11: ='Chi tiet'!H133 -> 0 | F11: ='Chi tiet'!I133 -> 0
A12: 7 | B12: Chi Hội đồng tư vấn | C12: ='Chi tiet'!F134 -> 7250000 | D12: ='Chi tiet'!G134 -> 0 | E12: ='Chi tiet'!H134 -> 7250000 | F12: ='Chi tiet'!I134 -> 0
A13: 8 | B13: Dịch vụ thuê ngoài phục vụ nghiên cứu | C13: ='Chi tiet'!F142 -> 0 | D13: ='Chi tiet'!G142 -> 0 | E13: ='Chi tiet'!H142 -> 0 | F13: ='Chi tiet'!I142 -> 0
A14: 9 | B14: Sửa chữa, mua sắm tài sản cố định | C14: ='Chi tiet'!F143 -> 0 | D14: ='Chi tiet'!G143 -> 0 | E14: ='Chi tiet'!H143 -> 0 | F14: ='Chi tiet'!I143 -> 0
A15: 10 | B15: Chi đoàn ra | C15: ='Chi tiet'!F144 -> 0 | D15: ='Chi tiet'!G144 -> 0 | E15: ='Chi tiet'!H144 -> 0 | F15: ='Chi tiet'!I144 -> 0
A16: 11 | B16: Chi khác | C16: ='Chi tiet'!F145 -> 0 | D16: ='Chi tiet'!G145 -> 0 | E16: ='Chi tiet'!H145 -> 0 | F16: ='Chi tiet'!I145 -> 0
A17: 12 | B17: Chi quản lý phí cơ quan chủ trì | C17: ='Chi tiet'!F147 -> 42000000 | D17: ='Chi tiet'!G145 -> 0 | E17: ='Chi tiet'!H147 -> 42000000 | F17: ='Chi tiet'!I145 -> 0
B18: Tổng cộng | C18: =ROUNDDOWN(SUM(C6:C17),-3) -> 900000000 | D18: =SUM(D7:D17) -> 0 | E18: =ROUNDDOWN(SUM(E6:E17),-3) -> 900000000 | F18: =SUM(F7:F17) -> 0
A20: 25. Kế hoạch phân bổ kinh phí
B22: Phân bổ kinh phí | C22: Đợt 1 | D22: Đợt 2 | E22: Đợt 3
B23: Ngân sách Nhà nước | C23: =E18/2 -> 450000000 | D23: =E18*0.4 -> 360000000 | E23: =E18-(C23+D23) -> 90000000
B24: Nguồn vốn khác | C24: =F18 -> 0
B25: Tổng cộng | C25: =SUM(C23:C24) -> 450000000 | D25: =SUM(D23:D24) -> 360000000 | E25: =SUM(E23:E24) -> 90000000
A27: IV. TỶ LỆ QUYỀN SỞ HỮU ĐỐI VỚI KẾT QUẢ NHIỆM VỤ
A28: 1. | B28: Sở Khoa học và Công nghệ TP.HCM | D28: =E18/(C18+D18) -> 1
A29: 2. | B29: Viện Khoa học và Công nghệ Tính toán | D29: =F18/(C18+D18) -> 0

Sheet Tong hop tien cong
A1: V. GIẢI TRÌNH CÁC KHOẢN CHI
B2: BẢNG TỔNG HỢP THANH TOÁN TIỀN CÔNG TRỰC TIẾP
A4: STT | B4: Họ và tên | C4: Chức danh | D4: Tổng số ngày công | E4: HS tiền công/ ngày | F4: Tổng tiền
A5: A | B5: Số ngày công, tiền công từng thành viên | F5: =(SUM(F6:F13)) -> 849747000
A6: 1 | B6: Nguyễn Hùng Sơn | C6: CNNV | D6: =SUMIF('Chi tiet'!$B$6:$B$128,'Tong hop tien cong'!B6,'Chi tiet'!$D$6:$D$128) -> 255 | E6: 0.79 | F6: =(+D6*E6*1490000) -> 300160500
A7: 2 | B7: Phạm Minh Trí | C7: TKKH,TVC | D7: =SUMIF('Chi tiet'!$B$6:$B$128,'Tong hop tien cong'!B7,'Chi tiet'!$D$6:$D$128) -> 80 | E7: 0.49 | F7: =(+D7*E7*1490000) -> 58408000
A8: 3 | B8: Võ Đình Bảy | C8: TVC | D8: =SUMIF('Chi tiet'!$B$6:$B$128,'Tong hop tien cong'!B8,'Chi tiet'!$D$6:$D$128) -> 215 | E8: 0.49 | F8: =(+D8*E8*1490000) -> 156971500
A9: 4 | B9: Nguyễn Thị Thuý Loan | C9: TVC | D9: =SUMIF('Chi tiet'!$B$6:$B$128,'Tong hop tien cong'!B9,'Chi tiet'!$D$6:$D$128) -> 149 | E9: 0.49 | F9: =(+D9*E9*1490000) -> 1.087849e+08
A10: 5 | B10: Nguyễn Bá Quang Lâm | C10: TVC | D10: =SUMIF('Chi tiet'!$B$6:$B$128,'Tong hop tien cong'!B10,'Chi tiet'!$D$6:$D$128) -> 141 | E10: 0.49 | F10: =(+D10*E10*1490000) -> 102944100
A11: 6 | B11: Lê Nhật Tùng | C11: TV | D11: =SUMIF('Chi tiet'!$B$6:$B$128,'Tong hop tien cong'!B11,'Chi tiet'!$D$6:$D$128) -> 142 | E11: 0.25 | F11: =(+D11*E11*1490000) -> 52895000
A12: 7 | B12: Phan Toại Tuyn | C12: TVC | D12: =SUMIF('Chi tiet'!$B$6:$B$128,'Tong hop tien cong'!B12,'Chi tiet'!$D$6:$D$128) -> 55 | E12: 0.49 | F12: =(+D12*E12*1490000) -> 40155500
A13: 8 | B13: Lê Thị Ngọc Thảo | C13: TV | D13: =SUMIF('Chi tiet'!$B$6:$B$128,'Tong hop tien cong'!B13,'Chi tiet'!$D$6:$D$128) -> 79 | E13: 0.25 | F13: =(+D13*E13*1490000) -> 29427500
A14: B | B14: Thuê chuyên gia | F14: 0
B15: Tổng cộng | D15: =SUM(D6:D14) -> 1116 | F15: =+F14+F5 -> 849747000
C21: =SUMIF('Chi tiet'!$B$6:$B$128,'Tong hop tien cong'!A21,'Chi tiet'!$D$6:$D$128) -> 0

Sheet Chi tiet
A1: BẢNG GIẢI TRÌNH CHI TIẾT
F2: Hệ số lương cơ bản: 1.490.000 đồng
A3: STT | B3: Nội dung công việc | C3: Đơn vị tính | D3: Số ngày công/số lượng | E3: Số tiền/Hệ số tiền công (hstcn) | F3: Thành tiền (Đồng) | H3: Nguồn kinh phí (Đồng)
F4: Khoán chi | G4: Ngoài khoán | H4: Ngân sách | I4: Khác
A5: 1 | B5: Tiền công lao động trực tiếp | D5: =SUM(D6,D9,D39,D75,D107,D126) -> 1116 | F5: =SUM(F6,F9,F39,F75,F107,F126) -> 849747000 | H5: =SUM(H6,H9,H39,H75,H107,H126) -> 849747000 | I5: =SUM(I6,I9,I39,I75,I126) -> 0
A6: 1.1 | B6: Xây dựng thuyết minh chi tiết đề tài | C6: Thuyết minh | D6: =SUM(D7:D8) -> 10 | F6: =SUM(F7:F8) -> 9536000 | H6: =F6 -> 9536000 | I6: 0
B7: Nguyễn Hùng Sơn | D7: 5 | E7: 0.79 | F7: =D7*E7*1490000 -> 5885500 | H7: =F7 -> 5885500
B8: Võ Đình Bảy | D8: 5 | E8: 0.49 | F8: =E8*D8*1490000 -> 3650500 | H8: =F8 -> 3650500
A9: 1.2 | B9: Nghiên cứu các chiến lược cắt tỉa ứng viên hiệu quả để khai thác các đồ thị con từ một đồ thị lớn | C9: Công | D9: =SUM(D10,D14,D18,D22,D26,D30,D34) -> 304 | F9: =SUM(F10,F14,F18,F22,F26,F30,F34) -> 231695000 | H9: =SUM(H10,H14,H18,H22,H26,H30,H34) -> 231695000
A10: 1.2.1 | B10: Phát biểu bài toán, định nghĩa, tính chất FSM trong một đồ thị có kích thước lớn | C10: Công | D10: =SUM(D11:D13) -> 40 | F10: =SUM(F11:F13) -> 31439000 | H10: =F10 -> 31439000
B11: Nguyễn Hùng Sơn | D11: 5 | E11: 0.79 | F11: =E11*D11*1490000 -> 5885500 | H11: =F11 -> 5885500
B12: Nguyễn Thị Thuý Loan | D12: 15 | E12: 0.49 | F12: =E12*D12*1490000 -> 10951500 | H12: =F12 -> 10951500
B13: Võ Đình Bảy | D13: 20 | E13: 0.49 | F13: =E13*D13*1490000 -> 14602000 | H13: =F13 -> 14602000
A14: 1.2.2 | B14: Đánh giá tổng quan các công trình về FSM | C14: Công | D14: =SUM(D15:D17) -> 40 | F14: =SUM(F15:F17) -> 26522000 | H14: =F14 -> 26522000
B15: Nguyễn Hùng Sơn | D15: 10 | E15: 0.79 | F15: =E15*D15*1490000 -> 11771000 | H15: =F15 -> 11771000
B16: Lê Nhật Tùng | D16: 20 | E16: 0.25 | F16: =E16*D16*1490000 -> 7450000 | H16: =F16 -> 7450000
B17: Phạm Minh Trí | D17: 10 | E17: 0.49 | F17: =E17*D17*1490000 -> 7301000 | H17: =F17 -> 7301000
A18: 1.2.3 | B18: Đánh giá các thuật toán GraMi, ScaleMine, SIGRAM, … | C18: Công | D18: =SUM(D19:D21) -> 45 | F18: =SUM(F19:F21) -> 37324500 | H18: =F18 -> 37324500 | I18: 0
B19: Nguyễn Hùng Sơn | D19: 10 | E19: 0.79 | F19: =E19*D19*1490000 -> 11771000 | H19: =F19 -> 11771000
B20: Nguyễn Bá Quang Lâm | D20: 15 | E20: 0.49 | F20: =E20*D20*1490000 -> 10951500 | H20: =F20 -> 10951500
B21: Nguyễn Thị Thuý Loan | D21: 20 | E21: 0.49 | F21: =E21*D21*1490000 -> 14602000 | H21: =F21 -> 14602000
A22: 1.2.4 | B22: Phát triển các định lý, tính chất áp dụng để tỉa sớm ứng viên | C22: Công | D22: =SUM(D23:D25) -> 30 | F22: =SUM(F23:F25) -> 26373000 | H22: =F22 -> 26373000 | I22: 0
B23: Nguyễn Hùng Sơn | D23: 10 | E23: 0.79 | F23: =E23*D23*1490000 -> 11771000 | H23: =F23 -> 11771000
B24: Phan Toại Tuyn | D24: 5 | E24: 0.49 | F24: =E24*D24*1490000 -> 3650500 | H24: =F24 -> 3650500
B25: Võ Đình Bảy | D25: 15 | E25: 0.49 | F25: =E25*D25*1490000 -> 10951500 | H25: =F25 -> 10951500
A26: 1.2.5 | B26: Phát triển thuật toán khai thác đồ thị con phổ biến | C26: Công | D26: =SUM(D27:D29) -> 50 | F26: =SUM(F27:F29) -> 33823000 | H26: =F26 -> 33823000 | I26: 0
B27: Nguyễn Hùng Sơn | D27: 10 | E27: 0.79 | F27: =E27*D27*1490000 -> 11771000 | H27: =F27 -> 11771000
B28: Nguyễn Thị Thuý Loan | D28: 20 | E28: 0.49 | F28: =E28*D28*1490000 -> 14602000 | H28: =F28 -> 14602000
B29: Lê Thị Ngọc Thảo | D29: 20 | E29: 0.25 | F29: =E29*D29*1490000 -> 7450000 | H29: =F29 -> 7450000
A30: 1.2.6 | B30: Lập trình, hiệu chỉnh các thuật toán liên quan | C30: Công | D30: =SUM(D31:D33) -> 45 | F30: =SUM(F31:F33) -> 37324500 | H30: =F30 -> 37324500 | I30: 0
B31: Nguyễn Hùng Sơn | D31: 10 | E31: 0.79 | F31: =E31*D31*1490000 -> 11771000 | H31: =F31 -> 11771000
B32: Phan Toại Tuyn | D32: 5 | E32: 0.49 | F32: =E32*D32*1490000 -> 3650500 | H32: =F32 -> 3650500
B33: Võ Đình Bảy | D33: 30 | E33: 0.49 | F33: =E33*D33*1490000 -> 21903000 | H33: =F33 -> 21903000
A34: 1.2.7 | B34: Phân tích, chọn lọc, hiệu chỉnh dữ liệu, tiến hành kiểm nghiệm để so sánh đánh giá kết quả | C34: Công | D34: =SUM(D35:D38) -> 54 | F34: =SUM(F35:F38) -> 38889000 | H34: =F34 -> 38889000 | I34: 0
B35: Nguyễn Hùng Sơn | D35: 10 | E35: 0.79 | F35: =E35*D35*1490000 -> 11771000 | H35: =F35 -> 11771000
B36: Phạm Minh Trí | D36: 15 | E36: 0.49 | F36: =E36*D36*1490000 -> 10951500 | H36: =F36 -> 10951500
B37: Lê Nhật Tùng | D37: 14 | E37: 0.25 | F37: =E37*D37*1490000 -> 5215000 | H37: =F37 -> 5215000
B38: Nguyễn Bá Quang Lâm | D38: 15 | E38: 0.49 | F38: =E38*D38*1490000 -> 10951500 | H38: =F38 -> 10951500
A39: 1.3 | B39: Đề xuất các thuật toán khai thác cho các đồ thị con đại diện như là các đồ thị con đóng và/hoặc các đồ thị con tối đại trong một đơn đồ thị kích thước lớn | C39: Công | D39: =SUM(D40,D44,D48,D52,D56,D60,D65,D69,D72) -> 330 | F39: =SUM(F40,F44,F48,F52,F56,F60,F65,F69,F72) -> 240933000 | H39: =F39 -> 240933000
A40: 1.3.1 | B40: Phân tích và kiểm nghiệm các mô hình gần đây cho khai thác các đồ thị con đại diện | C40: Công | D40: =SUM(D41:D43) -> 35 | F40: =SUM(F41:F43) -> 22871500 | H40: =F40 -> 22871500 | I40: 0
...
